Workbook
Name labs: Labs!#REF!

Sheet Summary
A1: ***Please summarize your answers for each question using tables/text/figures here***
A2: Ameya, Gurjar
A3: GPA: 3.56 | B3: Arizona State University
A6: Q1
A7: Total Units | B7: Column Labels
A8: Row Labels | B8: Med A | C8: Med B | D8: Grand Total
A9: Jul | B9: 4303700 | D9: 4303700
A10: Aug | B10: 4477100 | D10: 4477100
A11: Sep | B11: 849900 | C11: 535 | D11: 850435
A12: Oct | C12: 393 | D12: 393
A13: Nov | B13: 75300 | C13: 420 | D13: 75720
A14: Dec | B14: 10200 | C14: 1 | D14: 10201
A15: Grand Total | B15: 9716200 | C15: 1349 | D15: 9717549
A44: Q2
A45: Distinct Count of ID | B45: Column Labels
A46: Row Labels | B46: Med A | C46: Med B | D46: Grand Total
A47: Jul 2012 | B47: 92 | D47: 92
A48: Aug 2012 | B48: 92 | D48: 92
A49: Sep 2012 | B49: 73 | C49: 76 | D49: 87
A50: Oct 2012 | C50: 66 | D50: 66
A51: Nov 2012 | B51: 4 | C51: 72 | D51: 76
A52: Grand Total | B52: 110 | C52: 97 | D52: 126
A79: Q3
A80: Medication | B80: July | C80: August | D80: September | E80: October | F80: November
A81: Med A | B81: =IFERROR(ROUND(B9/B47,0),"No patients") -> 46779 | C81: =IFERROR(ROUND(B10/B48,0),"No patients") -> 48664 | D81: =IFERROR(ROUND(B11/B49,0),"No patients") -> 11642 | E81: =IFERROR(ROUND(B12/B50,0),"No patients") -> No patients | F81: =IFERROR(ROUND(B13/B51,0),"No patients") -> 18825
A82: Med B | B82: =IFERROR(ROUND(C9/C47,0),"No patients") -> No patients | C82: =IFERROR(ROUND(C10/C48,0),"No patients") -> No patients | D82: =ROUND(C11/C49,0) -> 7 | E82: =ROUND(C12/C50,0) -> 6 | F82: =ROUND(C13/C51,0) -> 6
A112: Helper Table | B112: for Q4 to Q11
B113: Column Labels
B114: Med A | D114: Med B | N114: (Months on B) | O114: Since Medicine B is given only once a month
A115: Row Labels | B115: First Date | C115: Last Date | D115: First Date | E115: Last Date | F115: Switched from A to B | G115: Started B Directly | H115: First B Month | I115: Weeks on Med A | J115: Months on Med A | K115: Total A Units | L115: Average Monthly A Units | M115: Total B Units | N115: No. of B Doses | O115: Average Monthly B Units | P115: First Med B Units | Q115: Second B Dose Date | R115: Second B Dose Units | S115: B2 vs B1 | T115: Avg Lab B on A | U115: Avg Lab B on B
A116: 1 | B116: 41092 | C116: 41157 | D116: 41164 | E116: 41241 | F116: =IF(AND(NOT(ISBLANK(B116)),NOT(ISBLANK(D116)),D116 > B116), "Yes", "No") -> Yes | G116: =IF(AND(ISBLANK(B116), NOT(ISBLANK(D116))), "Yes", "No") -> No | H116: =IF(NOT(ISBLANK(D116)), TEXT(D116, "mmm yyyy"), "Never Started B") -> Sep 2012 | I116: =IF(OR(B116="",C116=""),"", ((C116-B116)+1)/7) -> 9.4285714 | J116: =IF(I116="","", I116/4.33) -> 2.1774992 | K116: =SUMIFS( Admin!$D:$D, Admin!$A:$A, $A116, Admin!$B:$B, "Med A", Admin!$C:$C, ">=" & $B116, Admin!$C:$C, "<=" & $C116 ) -> 43800 | L116: =IF(AND(B116="",C116=""), "Never took A", IF(B116=C116, K116, IF(J116=0, 0, K116/J116) ) ) -> 20114.818 | M116: =SUMIFS(Admin!$D:$D,Admin!$A:$A,$A116, Admin!$B:$B,"Med B") -> 8 | N116: =COUNTIFS(Admin!$A:$A,$A116, Admin!$B:$B,"Med B") -> 3 | O116: =IF(N116=0,"Never took B",M116/N116) -> 2.6666667 | P116: =IF(D116="", "Never took B", SUMIFS(Admin!$D:$D, Admin!$A:$A,$A116, Admin!$B:$B,"Med B", Admin!$C:$C,D116) ) -> 4 | Q116: =IF(D116="","", EDATE(DATE(YEAR(D116),MONTH(D116),1),1) ) -> 41183 | R116: =IF(Q116="","", SUMIFS(Admin!$D:$D, Admin!$A:$A,$A116, Admin!$B:$B,"Med B", Admin!$C:$C,">="&Q116, Admin!$C:$C,"<"&EDATE(Q116,1)) ) -> 3 | S116: =IF(P116="Never took B","Never took B", IF(R116="No 2nd dose","No 2nd dose", IF(R116=P116,"Same", IF(R116>P116,"Higher","Lower") ) ) ) -> Lower | T116: =IFERROR( AVERAGEIFS( Labs!$D:$D, Labs!$A:$A,$A116, Labs!$C:$C,"LAB B", Labs!$B:$B,"<"&$D116 ), "" ) -> 10.38 | U116: =IFERROR( AVERAGEIFS( Labs!$D:$D, Labs!$A:$A,$A116, Labs!$C:$C,"LAB B", Labs!$B:$B,">="&$D116 ), "" ) -> 11.133333
A117: 2 | B117: 41093 | C117: 41139 | D117: 41165 | E117: 41165 | F117: =IF(AND(NOT(ISBLANK(B117)),NOT(ISBLANK(D117)),D117 > B117), "Yes", "No") -> Yes | G117: =IF(AND(ISBLANK(B117), NOT(ISBLANK(D117))), "Yes", "No") -> No | H117: =IF(NOT(ISBLANK(D117)), TEXT(D117, "mmm yyyy"), "Never Started B") -> Sep 2012 | I117: =IF(OR(B117="",C117=""),"", ((C117-B117)+1)/7) -> 6.7142857 | J117: =IF(I117="","", I117/4.33) -> 1.5506434 | K117: =SUMIFS( Admin!$D:$D, Admin!$A:$A, $A117, Admin!$B:$B, "Med A", Admin!$C:$C, ">=" & $B117, Admin!$C:$C, "<=" & $C117 ) -> 26900 | L117: =IF(AND(B117="",C117=""), "Never took A", IF(B117=C117, K117, IF(J117=0, 0, K117/J117) ) ) -> 17347.638 | M117: =SUMIFS(Admin!$D:$D,Admin!$A:$A,$A117, Admin!$B:$B,"Med B") -> 3 | N117: =COUNTIFS(Admin!$A:$A,$A117, Admin!$B:$B,"Med B") -> 1 | O117: =IF(N117=0,"Never took B",M117/N117) -> 3 | P117: =IF(D117="", "Never took B", SUMIFS(Admin!$D:$D, Admin!$A:$A,$A117, Admin!$B:$B,"Med B", Admin!$C:$C,D117) ) -> 3 | Q117: =IF(D117="","", EDATE(DATE(YEAR(D117),MONTH(D117),1),1) ) -> 41183 | R117: =IF(Q117="","", SUMIFS(Admin!$D:$D, Admin!$A:$A,$A117, Admin!$B:$B,"Med B", Admin!$C:$C,">="&Q117, Admin!$C:$C,"<"&EDATE(Q117,1)) ) -> 0 | S117: =IF(P117="Never took B","Never took B", IF(R117="No 2nd dose","No 2nd dose", IF(R117=P117,"Same", IF(R117>P117,"Higher","Lower") ) ) ) -> Lower | T117: =IFERROR( AVERAGEIFS( Labs!$D:$D, Labs!$A:$A,$A117, Labs!$C:$C,"LAB B", Labs!$B:$B,"<"&$D117 ), "" ) -> 11.085714 | U117: =IFERROR( AVERAGEIFS( Labs!$D:$D, Labs!$A:$A,$A117, Labs!$C:$C,"LAB B", Labs!$B:$B,">="&$D117 ), "" ) -> 11.78
A118: 3 | B118: 41092 | C118: 41094 | F118: =IF(AND(NOT(ISBLANK(B118)),NOT(ISBLANK(D118)),D118 > B118), "Yes", "No") -> No | G118: =IF(AND(ISBLANK(B118), NOT(ISBLANK(D118))), "Yes", "No") -> No | H118: =IF(NOT(ISBLANK(D118)), TEXT(D118, "mmm yyyy"), "Never Started B") -> Never Started B | I118: =IF(OR(B118="",C118=""),"", ((C118-B118)+1)/7) -> 0.42857143 | J118: =IF(I118="","", I118/4.33) -> 0.098977235 | K118: =SUMIFS( Admin!$D:$D, Admin!$A:$A, $A118, Admin!$B:$B, "Med A", Admin!$C:$C, ">=" & $B118, Admin!$C:$C, "<=" & $C118 ) -> 200 | L118: =IF(AND(B118="",C118=""), "Never took A", IF(B118=C118, K118, IF(J118=0, 0, K118/J118) ) ) -> 2020.6667 | M118: =SUMIFS(Admin!$D:$D,Admin!$A:$A,$A118, Admin!$B:$B,"Med B") -> 0 | N118: =COUNTIFS(Admin!$A:$A,$A118, Admin!$B:$B,"Med B") -> 0 | O118: =IF(N118=0,"Never took B",M118/N118) -> Never took B | P118: =IF(D118="", "Never took B", SUMIFS(Admin!$D:$D, Admin!$A:$A,$A118, Admin!$B:$B,"Med B", Admin!$C:$C,D118) ) -> Never took B | Q118: =IF(D118="","", EDATE(DATE(YEAR(D118),MONTH(D118),1),1) ) | R118: =IF(Q118="","", SUMIFS(Admin!$D:$D, Admin!$A:$A,$A118, Admin!$B:$B,"Med B", Admin!$C:$C,">="&Q118, Admin!$C:$C,"<"&EDATE(Q118,1)) ) | S118: =IF(P118="Never took B","Never took B", IF(R118="No 2nd dose","No 2nd dose", IF(R118=P118,"Same", IF(R118>P118,"Higher","Lower") ) ) ) -> Never took B | T118: =IFERROR( AVERAGEIFS( Labs!$D:$D, Labs!$A:$A,$A118, Labs!$C:$C,"LAB B", Labs!$B:$B,"<"&$D118 ), "" ) | U118: =IFERROR( AVERAGEIFS( Labs!$D:$D, Labs!$A:$A,$A118, Labs!$C:$C,"LAB B", Labs!$B:$B,">="&$D118 ), "" )
A119: 4 | B119: 41092 | C119: 41157 | D119: 41164 | E119: 41227 | F119: =IF(AND(NOT(ISBLANK(B119)),NOT(ISBLANK(D119)),D119 > B119), "Yes", "No") -> Yes | G119: =IF(AND(ISBLANK(B119), NOT(ISBLANK(D119))), "Yes", "No") -> No | H119: =IF(NOT(ISBLANK(D119)), TEXT(D119, "mmm yyyy"), "Never Started B") -> Sep 2012 | I119: =IF(OR(B119="",C119=""),"", ((C119-B119)+1)/7) -> 9.4285714 | J119: =IF(I119="","", I119/4.33) -> 2.1774992 | K119: =SUMIFS( Admin!$D:$D, Admin!$A:$A, $A119, Admin!$B:$B, "Med A", Admin!$C:$C, ">=" & $B119, Admin!$C:$C, "<=" & $C119 ) -> 36200 | L119: =IF(AND(B119="",C119=""), "Never took A", IF(B119=C119, K119, IF(J119=0, 0, K119/J119) ) ) -> 16624.576 | M119: =SUMIFS(Admin!$D:$D,Admin!$A:$A,$A119, Admin!$B:$B,"Med B") -> 4 | N119: =COUNTIFS(Admin!$A:$A,$A119, Admin!$B:$B,"Med B") -> 2 | O119: =IF(N119=0,"Never took B",M119/N119) -> 2 | P119: =IF(D119="", "Never took B", SUMIFS(Admin!$D:$D, Admin!$A:$A,$A119, Admin!$B:$B,"Med B", Admin!$C:$C,D119) ) -> 3 | Q119: =IF(D119="","", EDATE(DATE(YEAR(D119),MONTH(D119),1),1) ) -> 41183 | R119: =IF(Q119="","", SUMIFS(Admin!$D:$D, Admin!$A:$A,$A119, Admin!$B:$B,"Med B", Admin!$C:$C,">="&Q119, Admin!$C:$C,"<"&EDATE(Q119,1)) ) -> 0 | S119: =IF(P119="Never took B","Never took B", IF(R119="No 2nd dose","No 2nd dose", IF(R119=P119,"Same", IF(R119>P119,"Higher","Lower") ) ) ) -> Lower | T119: =IFERROR( AVERAGEIFS( Labs!$D:$D, Labs!$A:$A,$A119, Labs!$C:$C,"LAB B", Labs!$B:$B,"<"&$D119 ), "" ) -> 10.78 | U119: =IFERROR( AVERAGEIFS( Labs!$D:$D, Labs!$A:$A,$A119, Labs!$C:$C,"LAB B", Labs!$B:$B,">="&$D119 ), "" ) -> 12.02
A120: 5 | B120: 41096 | C120: 41136 | D120: 41164 | E120: 41227 | F120: =IF(AND(NOT(ISBLANK(B120)),NOT(ISBLANK(D120)),D120 > B120), "Yes", "No") -> Yes | G120: =IF(AND(ISBLANK(B120), NOT(ISBLANK(D120))), "Yes", "No") -> No | H120: =IF(NOT(ISBLANK(D120)), TEXT(D120, "mmm yyyy"), "Never Started B") -> Sep 2012 | I120: =IF(OR(B120="",C120=""),"", ((C120-B120)+1)/7) -> 5.8571429 | J120: =IF(I120="","", I120/4.33) -> 1.3526889 | K120: =SUMIFS( Admin!$D:$D, Admin!$A:$A, $A120, Admin!$B:$B, "Med A", Admin!$C:$C, ">=" & $B120, Admin!$C:$C, "<=" & $C120 ) -> 96900 | L120: =IF(AND(B120="",C120=""), "Never took A", IF(B120=C120, K120, IF(J120=0, 0, K120/J120) ) ) -> 71635.098 | M120: =SUMIFS(Admin!$D:$D,Admin!$A:$A,$A120, Admin!$B:$B,"Med B") -> 24 | N120: =COUNTIFS(Admin!$A:$A,$A120, Admin!$B:$B,"Med B") -> 3 | O120: =IF(N120=0,"Never took B",M120/N120) -> 8 | P120: =IF(D120="", "Never took B", SUMIFS(Admin!$D:$D, Admin!$A:$A,$A120, Admin!$B:$B,"Med B", Admin!$C:$C,D120) ) -> 8 | Q120: =IF(D120="","", EDATE(DATE(YEAR(D120),MONTH(D120),1),1) ) -> 41183 | R120: =IF(Q120="","", SUMIFS(Admin!$D:$D, Admin!$A:$A,$A120, Admin!$B:$B,"Med B", Admin!$C:$C,">="&Q120, Admin!$C:$C,"<"&EDATE(Q120,1)) ) -> 8 | S120: =IF(P120="Never took B","Never took B", IF(R120="No 2nd dose","No 2nd dose", IF(R120=P120,"Same", IF(R120>P120,"Higher","Lower") ) ) ) -> Same | T120: =IFERROR( AVERAGEIFS( Labs!$D:$D, Labs!$A:$A,$A120, Labs!$C:$C,"LAB B", Labs!$B:$B,"<"&$D120 ), "" ) -> 11.5 | U120: =IFERROR( AVERAGEIFS( Labs!$D:$D, Labs!$A:$A,$A120, Labs!$C:$C,"LAB B", Labs!$B:$B,">="&$D120 ), "" ) -> 10.328571
A121: 6 | B121: 41246 | C121: 41246 | F121: =IF(AND(NOT(ISBLANK(B121)),NOT(ISBLANK(D121)),D121 > B121), "Yes", "No") -> No | G121: =IF(AND(ISBLANK(B121), NOT(ISBLANK(D121))), "Yes", "No") -> No | H121: =IF(NOT(ISBLANK(D121)), TEXT(D121, "mmm yyyy"), "Never Started B") -> Never Started B | I121: =IF(OR(B121="",C121=""),"", ((C121-B121)+1)/7) -> 0.14285714 | J121: =IF(I121="","", I121/4.33) -> 0.032992412 | K121: =SUMIFS( Admin!$D:$D, Admin!$A:$A, $A121, Admin!$B:$B, "Med A", Admin!$C:$C, ">=" & $B121, Admin!$C:$C, "<=" & $C121 ) -> 3800 | L121: =IF(AND(B121="",C121=""), "Never took A", IF(B121=C121, K121, IF(J121=0, 0, K121/J121) ) ) -> 3800 | M121: =SUMIFS(Admin!$D:$D,Admin!$A:$A,$A121, Admin!$B:$B,"Med B") -> 0 | N121: =COUNTIFS(Admin!$A:$A,$A121, Admin!$B:$B,"Med B") -> 0 | O121: =IF(N121=0,"Never took B",M121/N121) -> Never took B | P121: =IF(D121="", "Never took B", SUMIFS(Admin!$D:$D, Admin!$A:$A,$A121, Admin!$B:$B,"Med B", Admin!$C:$C,D121) ) -> Never took B | Q121: =IF(D121="","", EDATE(DATE(YEAR(D121),MONTH(D121),1),1) ) | R121: =IF(Q121="","", SUMIFS(Admin!$D:$D, Admin!$A:$A,$A121, Admin!$B:$B,"Med B", Admin!$C:$C,">="&Q121, Admin!$C:$C,"<"&EDATE(Q121,1)) ) | S121: =IF(P121="Never took B","Never took B", IF(R121="No 2nd dose","No 2nd dose", IF(R121=P121,"Same", IF(R121>P121,"Higher","Lower") ) ) ) -> Never took B | T121: =IFERROR( AVERAGEIFS( Labs!$D:$D, Labs!$A:$A,$A121, Labs!$C:$C,"LAB B", Labs!$B:$B,"<"&$D121 ), "" ) | U121: =IFERROR( AVERAGEIFS( Labs!$D:$D, Labs!$A:$A,$A121, Labs!$C:$C,"LAB B", Labs!$B:$B,">="&$D121 ), "" )
A122: 7 | B122: 41093 | C122: 41109 | F122: =IF(AND(NOT(ISBLANK(B122)),NOT(ISBLANK(D122)),D122 > B122), "Yes", "No") -> No | G122: =IF(AND(ISBLANK(B122), NOT(ISBLANK(D122))), "Yes", "No") -> No | H122: =IF(NOT(ISBLANK(D122)), TEXT(D122, "mmm yyyy"), "Never Started B") -> Never Started B | I122: =IF(OR(B122="",C122=""),"", ((C122-B122)+1)/7) -> 2.4285714 | J122: =IF(I122="","", I122/4.33) -> 0.560871 | K122: =SUMIFS( Admin!$D:$D, Admin!$A:$A, $A122, Admin!$B:$B, "Med A", Admin!$C:$C, ">=" & $B122, Admin!$C:$C, "<=" & $C122 ) -> 44800 | L122: =IF(AND(B122="",C122=""), "Never took A", IF(B122=C122, K122, IF(J122=0, 0, K122/J122) ) ) -> 79875.765 | M122: =SUMIFS(Admin!$D:$D,Admin!$A:$A,$A122, Admin!$B:$B,"Med B") -> 0 | N122: =COUNTIFS(Admin!$A:$A,$A122, Admin!$B:$B,"Med B") -> 0 | O122: =IF(N122=0,"Never took B",M122/N122) -> Never took B | P122: =IF(D122="", "Never took B", SUMIFS(Admin!$D:$D, Admin!$A:$A,$A122, Admin!$B:$B,"Med B", Admin!$C:$C,D122) ) -> Never took B | Q122: =IF(D122="","", EDATE(DATE(YEAR(D122),MONTH(D122),1),1) ) | R122: =IF(Q122="","", SUMIFS(Admin!$D:$D, Admin!$A:$A,$A122, Admin!$B:$B,"Med B", Admin!$C:$C,">="&Q122, Admin!$C:$C,"<"&EDATE(Q122,1)) ) | S122: =IF(P122="Never took B","Never took B", IF(R122="No 2nd dose","No 2nd dose", IF(R122=P122,"Same", IF(R122>P122,"Higher","Lower") ) ) ) -> Never took B | T122: =IFERROR( AVERAGEIFS( Labs!$D:$D, Labs!$A:$A,$A122, Labs!$C:$C,"LAB B", Labs!$B:$B,"<"&$D122 ), "" ) | U122: =IFERROR( AVERAGEIFS( Labs!$D:$D, Labs!$A:$A,$A122, Labs!$C:$C,"LAB B", Labs!$B:$B,">="&$D122 ), "" )
A123: 8 | B123: 41093 | C123: 41158 | D123: 41165 | E123: 41228 | F123: =IF(AND(NOT(ISBLANK(B123)),NOT(ISBLANK(D123)),D123 > B123), "Yes", "No") -> Yes | G123: =IF(AND(ISBLANK(B123), NOT(ISBLANK(D123))), "Yes", "No") -> No | H123: =IF(NOT(ISBLANK(D123)), TEXT(D123, "mmm yyyy"), "Never Started B") -> Sep 2012 | I123: =IF(OR(B123="",C123=""),"", ((C123-B123)+1)/7) -> 9.4285714 | J123: =IF(I123="","", I123/4.33) -> 2.1774992 | K123: =SUMIFS( Admin!$D:$D, Admin!$A:$A, $A123, Admin!$B:$B, "Med A", Admin!$C:$C, ">=" & $B123, Admin!$C:$C, "<=" & $C123 ) -> 62100 | L123: =IF(AND(B123="",C123=""), "Never took A", IF(B123=C123, K123, IF(J123=0, 0, K123/J123) ) ) -> 28518.955 | M123: =SUMIFS(Admin!$D:$D,Admin!$A:$A,$A123, Admin!$B:$B,"Med B") -> 13 | N123: =COUNTIFS(Admin!$A:$A,$A123, Admin!$B:$B,"Med B") -> 3 | O123: =IF(N123=0,"Never took B",M123/N123) -> 4.3333333 | P123: =IF(D123="", "Never took B", SUMIFS(Admin!$D:$D, Admin!$A:$A,$A123, Admin!$B:$B,"Med B", Admin!$C:$C,D123) ) -> 5 | Q123: =IF(D123="","", EDATE(DATE(YEAR(D123),MONTH(D123),1),1) ) -> 41183 | R123: =IF(Q123="","", SUMIFS(Admin!$D:$D, Admin!$A:$A,$A123, Admin!$B:$B,"Med B", Admin!$C:$C,">="&Q123, Admin!$C:$C,"<"&EDATE(Q123,1)) ) -> 4 | S123: =IF(P123="Never took B","Never took B", IF(R123="No 2nd dose","No 2nd dose", IF(R123=P123,"Same", IF(R123>P123,"Higher","Lower") ) ) ) -> Lower | T123: =IFERROR( AVERAGEIFS( Labs!$D:$D, Labs!$A:$A,$A123, Labs!$C:$C,"LAB B", Labs!$B:$B,"<"&$D123 ), "" ) -> 10.62 | U123: =IFERROR( AVERAGEIFS( Labs!$D:$D, Labs!$A:$A,$A123, Labs!$C:$C,"LAB B", Labs!$B:$B,">="&$D123 ), "" ) -> 10.375
A124: 9 | B124: 41093 | C124: 41158 | D124: 41165 | E124: 41228 | F124: =IF(AND(NOT(ISBLANK(B124)),NOT(ISBLANK(D124)),D124 > B124), "Yes", "No") -> Yes | G124: =IF(AND(ISBLANK(B124), NOT(ISBLANK(D124))), "Yes", "No") -> No | H124: =IF(NOT(ISBLANK(D124)), TEXT(D124, "mmm yyyy"), "Never Started B") -> Sep 2012 | I124: =IF(OR(B124="",C124=""),"", ((C124-B124)+1)/7) -> 9.4285714 | J124: =IF(I124="","", I124/4.33) -> 2.1774992 | K124: =SUMIFS( Admin!$D:$D, Admin!$A:$A, $A124, Admin!$B:$B, "Med A", Admin!$C:$C, ">=" & $B124, Admin!$C:$C, "<=" & $C124 ) -> 67700 | L124: =IF(AND(B124="",C124=""), "Never took A", IF(B124=C124, K124, IF(J124=0, 0, K124/J124) ) ) -> 31090.712 | M124: =SUMIFS(Admin!$D:$D,Admin!$A:$A,$A124, Admin!$B:$B,"Med B") -> 20 | N124: =COUNTIFS(Admin!$A:$A,$A124, Admin!$B:$B,"Med B") -> 3 | O124: =IF(N124=0,"Never took B",M124/N124) -> 6.6666667 | P124: =IF(D124="", "Never took B", SUMIFS(Admin!$D:$D, Admin!$A:$A,$A124, Admin!$B:$B,"Med B", Admin!$C:$C,D124) ) -> 8 | Q124: =IF(D124="","", EDATE(DATE(YEAR(D124),MONTH(D124),1),1) ) -> 41183 | R124: =IF(Q124="","", SUMIFS(Admin!$D:$D, Admin!$A:$A,$A124, Admin!$B:$B,"Med B", Admin!$C:$C,">="&Q124, Admin!$C:$C,"<"&EDATE(Q124,1)) ) -> 6 | S124: =IF(P124="Never took B","Never took B", IF(R124="No 2nd dose","No 2nd dose", IF(R124=P124,"Same", IF(R124>P124,"Higher","Lower") ) ) ) -> Lower | T124: =IFERROR( AVERAGEIFS( Labs!$D:$D, Labs!$A:$A,$A124, Labs!$C:$C,"LAB B", Labs!$B:$B,"<"&$D124 ), "" ) -> 10.683333 | U124: =IFERROR( AVERAGEIFS( Labs!$D:$D, Labs!$A:$A,$A124, Labs!$C:$C,"LAB B", Labs!$B:$B,">="&$D124 ), "" ) -> 10.35
A125: 10 | B125: 41153 | C125: 41158 | D125: 41165 | E125: 41228 | F125: =IF(AND(NOT(ISBLANK(B125)),NOT(ISBLANK(D125)),D125 > B125), "Yes", "No") -> Yes | G125: =IF(AND(ISBLANK(B125), NOT(ISBLANK(D125))), "Yes", "No") -> No | H125: =IF(NOT(ISBLANK(D125)), TEXT(D125, "mmm yyyy"), "Never Started B") -> Sep 2012 | I125: =IF(OR(B125="",C125=""),"", ((C125-B125)+1)/7) -> 0.85714286 | J125: =IF(I125="","", I125/4.33) -> 0.19795447 | K125: =SUMIFS( Admin!$D:$D, Admin!$A:$A, $A125, Admin!$B:$B, "Med A", Admin!$C:$C, ">=" & $B125, Admin!$C:$C, "<=" & $C125 ) -> 11900 | L125: =IF(AND(B125="",C125=""), "Never took A", IF(B125=C125, K125, IF(J125=0, 0, K125/J125) ) ) -> 60114.833 | M125: =SUMIFS(Admin!$D:$D,Admin!$A:$A,$A125, Admin!$B:$B,"Med B") -> 24 | N125: =COUNTIFS(Admin!$A:$A,$A125, Admin!$B:$B,"Med B") -> 3 | O125: =IF(N125=0,"Never took B",M125/N125) -> 8 | P125: =IF(D125="", "Never took B", SUMIFS(Admin!$D:$D, Admin!$A:$A,$A125, Admin!$B:$B,"Med B", Admin!$C:$C,D125) ) -> 8 | Q125: =IF(D125="","", EDATE(DATE(YEAR(D125),MONTH(D125),1),1) ) -> 41183 | R125: =IF(Q125="","", SUMIFS(Admin!$D:$D, Admin!$A:$A,$A125, Admin!$B:$B,"Med B", Admin!$C:$C,">="&Q125, Admin!$C:$C,"<"&EDATE(Q125,1)) ) -> 8 | S125: =IF(P125="Never took B","Never took B", IF(R125="No 2nd dose","No 2nd dose", IF(R125=P125,"Same", IF(R125>P125,"Higher","Lower") ) ) ) -> Same | T125: =IFERROR( AVERAGEIFS( Labs!$D:$D, Labs!$A:$A,$A125, Labs!$C:$C,"LAB B", Labs!$B:$B,"<"&$D125 ), "" ) -> 9.35 | U125: =IFERROR( AVERAGEIFS( Labs!$D:$D, Labs!$A:$A,$A125, Labs!$C:$C,"LAB B", Labs!$B:$B,">="&$D125 ), "" ) -> 10.28
...

Sheet Admin
A1: ID | B1: Med | C1: Admin Date | D1: Units | E1: Month | G1: ***Please only use Excel to complete the practical test***
A2: 1 | B2: Med A | C2: 41092 | D2: 1500 | E2: =TEXT(C2,"mmm yyyy") -> Jul 2012
A3: 1 | B3: Med A | C3: 41096 | D3: 1500 | E3: =TEXT(C3,"mmm yyyy") -> Jul 2012
A4: 1 | B4: Med A | C4: 41099 | D4: 1500 | E4: =TEXT(C4,"mmm yyyy") -> Jul 2012
A5: 1 | B5: Med A | C5: 41101 | D5: 1500 | E5: =TEXT(C5,"mmm yyyy") -> Jul 2012
A6: 1 | B6: Med A | C6: 41103 | D6: 1500 | E6: =TEXT(C6,"mmm yyyy") -> Jul 2012
A7: 1 | B7: Med A | C7: 41106 | D7: 1500 | E7: =TEXT(C7,"mmm yyyy") -> Jul 2012
A8: 1 | B8: Med A | C8: 41110 | D8: 1500 | E8: =TEXT(C8,"mmm yyyy") -> Jul 2012
A9: 1 | B9: Med A | C9: 41113 | D9: 1500 | E9: =TEXT(C9,"mmm yyyy") -> Jul 2012
A10: 1 | B10: Med A | C10: 41115 | D10: 1700 | E10: =TEXT(C10,"mmm yyyy") -> Jul 2012
A11: 1 | B11: Med A | C11: 41117 | D11: 1700 | E11: =TEXT(C11,"mmm yyyy") -> Jul 2012
A12: 1 | B12: Med A | C12: 41120 | D12: 1700 | E12: =TEXT(C12,"mmm yyyy") -> Jul 2012
A13: 1 | B13: Med A | C13: 41122 | D13: 1700 | E13: =TEXT(C13,"mmm yyyy") -> Aug 2012
... A2023: 129 | B2023: Med B | C2023: 41165 | D2023: 10 | E2023: =TEXT(C2023,"mmm yyyy") -> Sep 2012

Sheet Labs
A1: ID | B1: DRAW_DATE | C1: LAB_RESULT_CODE | D1: LAB_VALUE
A2: 1 | B2: 41094 | C2: LAB A | D2: 679
A3: 1 | B3: 41122 | C3: LAB A | D3: 621
A4: 1 | B4: 41157 | C4: LAB A | D4: 915
A5: 1 | B5: 41185 | C5: LAB A | D5: 848
A6: 1 | B6: 41220 | C6: LAB A | D6: 845
A7: 1 | B7: 41248 | C7: LAB A | D7: 611
A8: 1 | B8: 41094 | C8: LAB B | D8: 10.7
A9: 1 | B9: 41110 | C9: LAB B | D9: 10.2
A10: 1 | B10: 41122 | C10: LAB B | D10: 10.3
A11: 1 | B11: 41138 | C11: LAB B | D11: 10.3
A12: 1 | B12: 41157 | C12: LAB B | D12: 10.4
A13: 1 | B13: 41171 | C13: LAB B | D13: 10.7
... A211: 12 | B211: 41185 | C211: LAB C | D211: 19
A212: #N/A | B212: 41094 | C212: LAB A | D212: 694
A213: #N/A | B213: 41122 | C213: LAB A | D213: 955
A214: #N/A | B214: 41172 | C214: LAB A | D214: 675
A215: #N/A | B215: 41185 | C215: LAB A | D215: 1049
A216: #N/A | B216: 41220 | C216: LAB A | D216: 626
A217: #N/A | B217: 41094 | C217: LAB B | D217: 11.7
A218: #N/A | B218: 41101 | C218: LAB B | D218: 12.1
A219: #N/A | B219: 41108 | C219: LAB B | D219: 11.8
A220: #N/A | B220: 41115 | C220: LAB B | D220: 12
A221: #N/A | B221: 41122 | C221: LAB B | D221: 12.2
A222: #N/A | B222: 41129 | C222: LAB B | D222: 12.7
A223: #N/A | B223: 41136 | C223: LAB B | D223: 12
... A236: #N/A | B236: 41220 | C236: LAB C | D236: 27
A237: 14 | B237: 41094 | C237: LAB A | D237: 696
A238: 14 | B238: 41122 | C238: LAB A | D238: 1284
A239: 14 | B239: 41157 | C239: LAB A | D239: 1462
A240: 14 | B240: 41094 | C240: LAB B | D240: 10.8
A241: 14 | B241: 41108 | C241: LAB B | D241: 11.2
A242: 14 | B242: 41122 | C242: LAB B | D242: 11
A243: 14 | B243: 41136 | C243: LAB B | D243: 11.1
A244: 14 | B244: 41157 | C244: LAB B | D244: 11.9
A245: 14 | B245: 41171 | C245: LAB B | D245: 11.1
A246: 14 | B246: 41094 | C246: LAB C | D246: 19
A247: 14 | B247: 41122 | C247: LAB C | D247: 14
A248: 14 | B248: 41157 | C248: LAB C | D248: 34
... A273: 15 | B273: 41248 | C273: LAB C | D273: 29
...
